Already up to date.

[0:17:04.115479302] [3378] [1;32m INFO [1;37mCamera [1;34mcamera_manager.cpp:325 [0mlibcamera v0.3.2+27-7330f29b
[0:17:04.144630278] [3411] [1;33m WARN [1;37mRPiSdn [1;34msdn.cpp:40 [0mUsing legacy SDN tuning - please consider moving SDN inside rpi.denoise
[0:17:04.146757340] [3411] [1;32m INFO [1;37mRPI [1;34mvc4.cpp:447 [0mRegistered camera /base/soc/i2c0mux/i2c@1/imx708@1a to Unicam device /dev/media2 and ISP device /dev/media0
[0:17:04.146837539] [3411] [1;32m INFO [1;37mRPI [1;34mpipeline_base.cpp:1126 [0mUsing configuration file '/usr/share/libcamera/pipeline/rpi/vc4/rpi_apps.yaml'
[0:17:04.153498377] [3378] [1;32m INFO [1;37mCamera [1;34mcamera.cpp:1197 [0mconfiguring streams: (0) 640x480-XBGR8888 (1) 1536x864-SBGGR10_CSI2P
[0:17:04.153957166] [3411] [1;32m INFO [1;37mRPI [1;34mvc4.cpp:622 [0mSensor: /base/soc/i2c0mux/i2c@1/imx708@1a - Selected sensor format: 1536x864-SBGGR10_1X10 - Selected unicam format: 1536x864-pBAA
email sent!
unknown num: 57
 * Serving Flask app 'flaskApp'
 * Debug mode: off
WARNING: This is a development server. Do not use it in a production deployment. Use a production WSGI server instead.
 * Running on all addresses (0.0.0.0)
 * Running on http://127.0.0.1:3000
 * Running on http://192.168.157.27:3000
Press CTRL+C to quit
192.168.157.54 - - [06/Dec/2024 09:51:50] "GET /stream HTTP/1.1" 200 -
192.168.157.54 - - [06/Dec/2024 09:51:50] "GET /static/stream.js HTTP/1.1" 304 -
192.168.157.54 - - [06/Dec/2024 09:51:50] "GET /static/styles.css HTTP/1.1" 304 -
192.168.157.54 - - [06/Dec/2024 09:51:50] "GET /stream/security_footage HTTP/1.1" 200 -
[2024-12-06 09:51:50,762] ERROR in app: Exception on /favicon.ico [GET]
Traceback (most recent call last):
  File "/home/jmund/ShockerSecurity/venv/lib/python3.11/site-packages/flask/app.py", line 880, in full_dispatch_request
    rv = self.dispatch_request()
         ^^^^^^^^^^^^^^^^^^^^^^^
  File "/home/jmund/ShockerSecurity/venv/lib/python3.11/site-packages/flask/app.py", line 854, in dispatch_request
    self.raise_routing_exception(req)
  File "/home/jmund/ShockerSecurity/venv/lib/python3.11/site-packages/flask/app.py", line 463, in raise_routing_exception
    raise request.routing_exception  # type: ignore[misc]
    ^^^^^^^^^^^^^^^^^^^^^^^^^^^^^^^
  File "/home/jmund/ShockerSecurity/venv/lib/python3.11/site-packages/flask/ctx.py", line 362, in match_request
    result = self.url_adapter.match(return_rule=True)  # type: ignore
             ^^^^^^^^^^^^^^^^^^^^^^^^^^^^^^^^^^^^^^^^
  File "/home/jmund/ShockerSecurity/venv/lib/python3.11/site-packages/werkzeug/routing/map.py", line 629, in match
    raise NotFound() from None
werkzeug.exceptions.NotFound: 404 Not Found: The requested URL was not found on the server. If you entered the URL manually please check your spelling and try again.

During handling of the above exception, another exception occurred:

Traceback (most recent call last):
  File "/home/jmund/ShockerSecurity/venv/lib/python3.11/site-packages/flask/app.py", line 1473, in wsgi_app
    response = self.full_dispatch_request()
               ^^^^^^^^^^^^^^^^^^^^^^^^^^^^
  File "/home/jmund/ShockerSecurity/venv/lib/python3.11/site-packages/flask/app.py", line 882, in full_dispatch_request
    rv = self.handle_user_exception(e)
         ^^^^^^^^^^^^^^^^^^^^^^^^^^^^^
  File "/usr/lib/python3/dist-packages/flask_cors/extension.py", line 165, in wrapped_function
    return cors_after_request(app.make_response(f(*args, **kwargs)))
                              ^^^^^^^^^^^^^^^^^^^^^^^^^^^^^^^^^^^^^
  File "/home/jmund/ShockerSecurity/venv/lib/python3.11/site-packages/flask/app.py", line 1174, in make_response
    raise TypeError(
TypeError: The view function for None did not return a valid response. The function either returned None or ended without a return statement.
192.168.157.54 - - [06/Dec/2024 09:51:50] "GET /favicon.ico HTTP/1.1" 500 -
Error on request:
Traceback (most recent call last):
  File "/home/jmund/ShockerSecurity/venv/lib/python3.11/site-packages/flask/app.py", line 880, in full_dispatch_request
    rv = self.dispatch_request()
         ^^^^^^^^^^^^^^^^^^^^^^^
  File "/home/jmund/ShockerSecurity/venv/lib/python3.11/site-packages/flask/app.py", line 854, in dispatch_request
    self.raise_routing_exception(req)
  File "/home/jmund/ShockerSecurity/venv/lib/python3.11/site-packages/flask/app.py", line 463, in raise_routing_exception
    raise request.routing_exception  # type: ignore[misc]
  File "/home/jmund/ShockerSecurity/venv/lib/python3.11/site-packages/flask/ctx.py", line 362, in match_request
    result = self.url_adapter.match(return_rule=True)  # type: ignore
             ^^^^^^^^^^^^^^^^^^^^^^^^^^^^^^^^^^^^^^^^^^^^^^^^^^^^^^^^
  File "/home/jmund/ShockerSecurity/venv/lib/python3.11/site-packages/werkzeug/routing/map.py", line 629, in match
    raise NotFound() from None
werkzeug.exceptions.NotFound: 404 Not Found: The requested URL was not found on the server. If you entered the URL manually please check your spelling and try again.

During handling of the above exception, another exception occurred:

Traceback (most recent call last):
  File "/home/jmund/ShockerSecurity/venv/lib/python3.11/site-packages/flask/app.py", line 1473, in wsgi_app
    response = self.full_dispatch_request()
               ^^^^^^^^^^^^^^^^^^^^^^^^^^^^
  File "/home/jmund/ShockerSecurity/venv/lib/python3.11/site-packages/flask/app.py", line 882, in full_dispatch_request
    rv = self.handle_user_exception(e)
         ^^^^^^^^^^^^^^^^^^^^^^^^^^^^^
  File "/usr/lib/python3/dist-packages/flask_cors/extension.py", line 165, in wrapped_function
    return cors_after_request(app.make_response(f(*args, **kwargs)))
                              ^^^^^^^^^^^^^^^^^^^^^^^^^^^^^^^^^^^^^^
  File "/home/jmund/ShockerSecurity/venv/lib/python3.11/site-packages/flask/app.py", line 1174, in make_response
    raise TypeError(
TypeError: The view function for None did not return a valid response. The function either returned None or ended without a return statement.

During handling of the above exception, another exception occurred:

Traceback (most recent call last):
  File "/home/jmund/ShockerSecurity/venv/lib/python3.11/site-packages/werkzeug/serving.py", line 370, in run_wsgi
    execute(self.server.app)
  File "/home/jmund/ShockerSecurity/venv/lib/python3.11/site-packages/werkzeug/serving.py", line 331, in execute
    application_iter = app(environ, start_response)
                       ^^^^^^^^^^^^^^^^^^^^^^^^^^^^
  File "/home/jmund/ShockerSecurity/venv/lib/python3.11/site-packages/flask/app.py", line 1498, in __call__
    return self.wsgi_app(environ, start_response)
           ^^^^^^^^^^^^^^^^^^^^^^^^^^^^^^^^^^^^^^
  File "/home/jmund/ShockerSecurity/venv/lib/python3.11/site-packages/flask/app.py", line 1476, in wsgi_app
    response = self.handle_exception(e)
               ^^^^^^^^^^^^^^^^^^^^^^^^
  File "/usr/lib/python3/dist-packages/flask_cors/extension.py", line 165, in wrapped_function
    return cors_after_request(app.make_response(f(*args, **kwargs)))
                                                ^^^^^^^^^^^^^^^^^^^^
  File "/home/jmund/ShockerSecurity/venv/lib/python3.11/site-packages/flask/app.py", line 825, in handle_exception
    return self.finalize_request(server_error, from_error_handler=True)
           ^^^^^^^^^^^^^^^^^^^^^^^^^^^^^^^^^^^^^^^^^^^^^^^^^^^^^^^^^^^^
  File "/home/jmund/ShockerSecurity/venv/lib/python3.11/site-packages/flask/app.py", line 902, in finalize_request
    response = self.make_response(rv)
               ^^^^^^^^^^^^^^^^^^^^^^
  File "/home/jmund/ShockerSecurity/venv/lib/python3.11/site-packages/flask/app.py", line 1174, in make_response
    raise TypeError(
TypeError: The view function for None did not return a valid response. The function either returned None or ended without a return statement.
192.168.157.54 - - [06/Dec/2024 09:51:53] "GET /faces HTTP/1.1" 200 -
192.168.157.54 - - [06/Dec/2024 09:51:53] "GET /static/styles.css HTTP/1.1" 304 -
192.168.157.54 - - [06/Dec/2024 09:51:53] "GET /static/manageFaces.js HTTP/1.1" 304 -
192.168.157.54 - - [06/Dec/2024 09:51:53] "GET /faces/data HTTP/1.1" 200 -
[2024-12-06 09:51:53,613] ERROR in app: Exception on /favicon.ico [GET]
Traceback (most recent call last):
  File "/home/jmund/ShockerSecurity/venv/lib/python3.11/site-packages/flask/app.py", line 880, in full_dispatch_request
    rv = self.dispatch_request()
         ^^^^^^^^^^^^^^^^^^^^^^^
  File "/home/jmund/ShockerSecurity/venv/lib/python3.11/site-packages/flask/app.py", line 854, in dispatch_request
    self.raise_routing_exception(req)
  File "/home/jmund/ShockerSecurity/venv/lib/python3.11/site-packages/flask/app.py", line 463, in raise_routing_exception
    raise request.routing_exception  # type: ignore[misc]
    ^^^^^^^^^^^^^^^^^^^^^^^^^^^^^^^
  File "/home/jmund/ShockerSecurity/venv/lib/python3.11/site-packages/flask/ctx.py", line 362, in match_request
    result = self.url_adapter.match(return_rule=True)  # type: ignore
             ^^^^^^^^^^^^^^^^^^^^^^^^^^^^^^^^^^^^^^^^
  File "/home/jmund/ShockerSecurity/venv/lib/python3.11/site-packages/werkzeug/routing/map.py", line 629, in match
    raise NotFound() from None
werkzeug.exceptions.NotFound: 404 Not Found: The requested URL was not found on the server. If you entered the URL manually please check your spelling and try again.

During handling of the above exception, another exception occurred:

Traceback (most recent call last):
  File "/home/jmund/ShockerSecurity/venv/lib/python3.11/site-packages/flask/app.py", line 1473, in wsgi_app
    response = self.full_dispatch_request()
               ^^^^^^^^^^^^^^^^^^^^^^^^^^^^
  File "/home/jmund/ShockerSecurity/venv/lib/python3.11/site-packages/flask/app.py", line 882, in full_dispatch_request
    rv = self.handle_user_exception(e)
         ^^^^^^^^^^^^^^^^^^^^^^^^^^^^^
  File "/usr/lib/python3/dist-packages/flask_cors/extension.py", line 165, in wrapped_function
    return cors_after_request(app.make_response(f(*args, **kwargs)))
                              ^^^^^^^^^^^^^^^^^^^^^^^^^^^^^^^^^^^^^
  File "/home/jmund/ShockerSecurity/venv/lib/python3.11/site-packages/flask/app.py", line 1174, in make_response
    raise TypeError(
TypeError: The view function for None did not return a valid response. The function either returned None or ended without a return statement.
192.168.157.54 - - [06/Dec/2024 09:51:53] "GET /favicon.ico HTTP/1.1" 500 -
Error on request:
Traceback (most recent call last):
  File "/home/jmund/ShockerSecurity/venv/lib/python3.11/site-packages/flask/app.py", line 880, in full_dispatch_request
    rv = self.dispatch_request()
         ^^^^^^^^^^^^^^^^^^^^^^^
  File "/home/jmund/ShockerSecurity/venv/lib/python3.11/site-packages/flask/app.py", line 854, in dispatch_request
    self.raise_routing_exception(req)
  File "/home/jmund/ShockerSecurity/venv/lib/python3.11/site-packages/flask/app.py", line 463, in raise_routing_exception
    raise request.routing_exception  # type: ignore[misc]
  File "/home/jmund/ShockerSecurity/venv/lib/python3.11/site-packages/flask/ctx.py", line 362, in match_request
    result = self.url_adapter.match(return_rule=True)  # type: ignore
             ^^^^^^^^^^^^^^^^^^^^^^^^^^^^^^^^^^^^^^^^^^^^^^^^^^^^^^^^
  File "/home/jmund/ShockerSecurity/venv/lib/python3.11/site-packages/werkzeug/routing/map.py", line 629, in match
    raise NotFound() from None
werkzeug.exceptions.NotFound: 404 Not Found: The requested URL was not found on the server. If you entered the URL manually please check your spelling and try again.

During handling of the above exception, another exception occurred:

Traceback (most recent call last):
  File "/home/jmund/ShockerSecurity/venv/lib/python3.11/site-packages/flask/app.py", line 1473, in wsgi_app
    response = self.full_dispatch_request()
               ^^^^^^^^^^^^^^^^^^^^^^^^^^^^
  File "/home/jmund/ShockerSecurity/venv/lib/python3.11/site-packages/flask/app.py", line 882, in full_dispatch_request
    rv = self.handle_user_exception(e)
         ^^^^^^^^^^^^^^^^^^^^^^^^^^^^^
  File "/usr/lib/python3/dist-packages/flask_cors/extension.py", line 165, in wrapped_function
    return cors_after_request(app.make_response(f(*args, **kwargs)))
                              ^^^^^^^^^^^^^^^^^^^^^^^^^^^^^^^^^^^^^^
  File "/home/jmund/ShockerSecurity/venv/lib/python3.11/site-packages/flask/app.py", line 1174, in make_response
    raise TypeError(
TypeError: The view function for None did not return a valid response. The function either returned None or ended without a return statement.

During handling of the above exception, another exception occurred:

Traceback (most recent call last):
  File "/home/jmund/ShockerSecurity/venv/lib/python3.11/site-packages/werkzeug/serving.py", line 370, in run_wsgi
    execute(self.server.app)
  File "/home/jmund/ShockerSecurity/venv/lib/python3.11/site-packages/werkzeug/serving.py", line 331, in execute
    application_iter = app(environ, start_response)
                       ^^^^^^^^^^^^^^^^^^^^^^^^^^^^
  File "/home/jmund/ShockerSecurity/venv/lib/python3.11/site-packages/flask/app.py", line 1498, in __call__
    return self.wsgi_app(environ, start_response)
           ^^^^^^^^^^^^^^^^^^^^^^^^^^^^^^^^^^^^^^
  File "/home/jmund/ShockerSecurity/venv/lib/python3.11/site-packages/flask/app.py", line 1476, in wsgi_app
    response = self.handle_exception(e)
               ^^^^^^^^^^^^^^^^^^^^^^^^
  File "/usr/lib/python3/dist-packages/flask_cors/extension.py", line 165, in wrapped_function
    return cors_after_request(app.make_response(f(*args, **kwargs)))
                                                ^^^^^^^^^^^^^^^^^^^^
  File "/home/jmund/ShockerSecurity/venv/lib/python3.11/site-packages/flask/app.py", line 825, in handle_exception
    return self.finalize_request(server_error, from_error_handler=True)
           ^^^^^^^^^^^^^^^^^^^^^^^^^^^^^^^^^^^^^^^^^^^^^^^^^^^^^^^^^^^^
  File "/home/jmund/ShockerSecurity/venv/lib/python3.11/site-packages/flask/app.py", line 902, in finalize_request
    response = self.make_response(rv)
               ^^^^^^^^^^^^^^^^^^^^^^
  File "/home/jmund/ShockerSecurity/venv/lib/python3.11/site-packages/flask/app.py", line 1174, in make_response
    raise TypeError(
TypeError: The view function for None did not return a valid response. The function either returned None or ended without a return statement.
192.168.157.54 - - [06/Dec/2024 09:51:55] "GET /stream HTTP/1.1" 200 -
192.168.157.54 - - [06/Dec/2024 09:51:55] "GET /static/styles.css HTTP/1.1" 304 -
192.168.157.54 - - [06/Dec/2024 09:51:55] "GET /static/stream.js HTTP/1.1" 304 -
192.168.157.54 - - [06/Dec/2024 09:51:55] "GET /stream/security_footage HTTP/1.1" 200 -
[2024-12-06 09:51:55,822] ERROR in app: Exception on /favicon.ico [GET]
Traceback (most recent call last):
  File "/home/jmund/ShockerSecurity/venv/lib/python3.11/site-packages/flask/app.py", line 880, in full_dispatch_request
    rv = self.dispatch_request()
         ^^^^^^^^^^^^^^^^^^^^^^^
  File "/home/jmund/ShockerSecurity/venv/lib/python3.11/site-packages/flask/app.py", line 854, in dispatch_request
    self.raise_routing_exception(req)
  File "/home/jmund/ShockerSecurity/venv/lib/python3.11/site-packages/flask/app.py", line 463, in raise_routing_exception
    raise request.routing_exception  # type: ignore[misc]
    ^^^^^^^^^^^^^^^^^^^^^^^^^^^^^^^
  File "/home/jmund/ShockerSecurity/venv/lib/python3.11/site-packages/flask/ctx.py", line 362, in match_request
    result = self.url_adapter.match(return_rule=True)  # type: ignore
             ^^^^^^^^^^^^^^^^^^^^^^^^^^^^^^^^^^^^^^^^
  File "/home/jmund/ShockerSecurity/venv/lib/python3.11/site-packages/werkzeug/routing/map.py", line 629, in match
    raise NotFound() from None
werkzeug.exceptions.NotFound: 404 Not Found: The requested URL was not found on the server. If you entered the URL manually please check your spelling and try again.

During handling of the above exception, another exception occurred:

Traceback (most recent call last):
  File "/home/jmund/ShockerSecurity/venv/lib/python3.11/site-packages/flask/app.py", line 1473, in wsgi_app
    response = self.full_dispatch_request()
               ^^^^^^^^^^^^^^^^^^^^^^^^^^^^
  File "/home/jmund/ShockerSecurity/venv/lib/python3.11/site-packages/flask/app.py", line 882, in full_dispatch_request
    rv = self.handle_user_exception(e)
         ^^^^^^^^^^^^^^^^^^^^^^^^^^^^^
  File "/usr/lib/python3/dist-packages/flask_cors/extension.py", line 165, in wrapped_function
    return cors_after_request(app.make_response(f(*args, **kwargs)))
                              ^^^^^^^^^^^^^^^^^^^^^^^^^^^^^^^^^^^^^
  File "/home/jmund/ShockerSecurity/venv/lib/python3.11/site-packages/flask/app.py", line 1174, in make_response
    raise TypeError(
TypeError: The view function for None did not return a valid response. The function either returned None or ended without a return statement.
192.168.157.54 - - [06/Dec/2024 09:51:55] "GET /favicon.ico HTTP/1.1" 500 -
Error on request:
Traceback (most recent call last):
  File "/home/jmund/ShockerSecurity/venv/lib/python3.11/site-packages/flask/app.py", line 880, in full_dispatch_request
    rv = self.dispatch_request()
         ^^^^^^^^^^^^^^^^^^^^^^^
  File "/home/jmund/ShockerSecurity/venv/lib/python3.11/site-packages/flask/app.py", line 854, in dispatch_request
    self.raise_routing_exception(req)
  File "/home/jmund/ShockerSecurity/venv/lib/python3.11/site-packages/flask/app.py", line 463, in raise_routing_exception
    raise request.routing_exception  # type: ignore[misc]
  File "/home/jmund/ShockerSecurity/venv/lib/python3.11/site-packages/flask/ctx.py", line 362, in match_request
    result = self.url_adapter.match(return_rule=True)  # type: ignore
             ^^^^^^^^^^^^^^^^^^^^^^^^^^^^^^^^^^^^^^^^^^^^^^^^^^^^^^^^
  File "/home/jmund/ShockerSecurity/venv/lib/python3.11/site-packages/werkzeug/routing/map.py", line 629, in match
    raise NotFound() from None
werkzeug.exceptions.NotFound: 404 Not Found: The requested URL was not found on the server. If you entered the URL manually please check your spelling and try again.

During handling of the above exception, another exception occurred:

Traceback (most recent call last):
  File "/home/jmund/ShockerSecurity/venv/lib/python3.11/site-packages/flask/app.py", line 1473, in wsgi_app
    response = self.full_dispatch_request()
               ^^^^^^^^^^^^^^^^^^^^^^^^^^^^
  File "/home/jmund/ShockerSecurity/venv/lib/python3.11/site-packages/flask/app.py", line 882, in full_dispatch_request
    rv = self.handle_user_exception(e)
         ^^^^^^^^^^^^^^^^^^^^^^^^^^^^^
  File "/usr/lib/python3/dist-packages/flask_cors/extension.py", line 165, in wrapped_function
    return cors_after_request(app.make_response(f(*args, **kwargs)))
                              ^^^^^^^^^^^^^^^^^^^^^^^^^^^^^^^^^^^^^^
  File "/home/jmund/ShockerSecurity/venv/lib/python3.11/site-packages/flask/app.py", line 1174, in make_response
    raise TypeError(
TypeError: The view function for None did not return a valid response. The function either returned None or ended without a return statement.

During handling of the above exception, another exception occurred:

Traceback (most recent call last):
  File "/home/jmund/ShockerSecurity/venv/lib/python3.11/site-packages/werkzeug/serving.py", line 370, in run_wsgi
    execute(self.server.app)
  File "/home/jmund/ShockerSecurity/venv/lib/python3.11/site-packages/werkzeug/serving.py", line 331, in execute
    application_iter = app(environ, start_response)
                       ^^^^^^^^^^^^^^^^^^^^^^^^^^^^
  File "/home/jmund/ShockerSecurity/venv/lib/python3.11/site-packages/flask/app.py", line 1498, in __call__
    return self.wsgi_app(environ, start_response)
           ^^^^^^^^^^^^^^^^^^^^^^^^^^^^^^^^^^^^^^
  File "/home/jmund/ShockerSecurity/venv/lib/python3.11/site-packages/flask/app.py", line 1476, in wsgi_app
    response = self.handle_exception(e)
               ^^^^^^^^^^^^^^^^^^^^^^^^
  File "/usr/lib/python3/dist-packages/flask_cors/extension.py", line 165, in wrapped_function
    return cors_after_request(app.make_response(f(*args, **kwargs)))
                                                ^^^^^^^^^^^^^^^^^^^^
  File "/home/jmund/ShockerSecurity/venv/lib/python3.11/site-packages/flask/app.py", line 825, in handle_exception
    return self.finalize_request(server_error, from_error_handler=True)
           ^^^^^^^^^^^^^^^^^^^^^^^^^^^^^^^^^^^^^^^^^^^^^^^^^^^^^^^^^^^^
  File "/home/jmund/ShockerSecurity/venv/lib/python3.11/site-packages/flask/app.py", line 902, in finalize_request
    response = self.make_response(rv)
               ^^^^^^^^^^^^^^^^^^^^^^
  File "/home/jmund/ShockerSecurity/venv/lib/python3.11/site-packages/flask/app.py", line 1174, in make_response
    raise TypeError(
TypeError: The view function for None did not return a valid response. The function either returned None or ended without a return statement.
192.168.157.54 - - [06/Dec/2024 09:52:09] "GET /faces HTTP/1.1" 200 -
192.168.157.54 - - [06/Dec/2024 09:52:10] "GET /static/manageFaces.js HTTP/1.1" 304 -
192.168.157.54 - - [06/Dec/2024 09:52:10] "GET /static/styles.css HTTP/1.1" 304 -
192.168.157.54 - - [06/Dec/2024 09:52:10] "GET /faces/data HTTP/1.1" 200 -
[2024-12-06 09:52:10,194] ERROR in app: Exception on /favicon.ico [GET]
Traceback (most recent call last):
  File "/home/jmund/ShockerSecurity/venv/lib/python3.11/site-packages/flask/app.py", line 880, in full_dispatch_request
    rv = self.dispatch_request()
         ^^^^^^^^^^^^^^^^^^^^^^^
  File "/home/jmund/ShockerSecurity/venv/lib/python3.11/site-packages/flask/app.py", line 854, in dispatch_request
    self.raise_routing_exception(req)
  File "/home/jmund/ShockerSecurity/venv/lib/python3.11/site-packages/flask/app.py", line 463, in raise_routing_exception
    raise request.routing_exception  # type: ignore[misc]
    ^^^^^^^^^^^^^^^^^^^^^^^^^^^^^^^
  File "/home/jmund/ShockerSecurity/venv/lib/python3.11/site-packages/flask/ctx.py", line 362, in match_request
    result = self.url_adapter.match(return_rule=True)  # type: ignore
             ^^^^^^^^^^^^^^^^^^^^^^^^^^^^^^^^^^^^^^^^
  File "/home/jmund/ShockerSecurity/venv/lib/python3.11/site-packages/werkzeug/routing/map.py", line 629, in match
    raise NotFound() from None
werkzeug.exceptions.NotFound: 404 Not Found: The requested URL was not found on the server. If you entered the URL manually please check your spelling and try again.

During handling of the above exception, another exception occurred:

Traceback (most recent call last):
  File "/home/jmund/ShockerSecurity/venv/lib/python3.11/site-packages/flask/app.py", line 1473, in wsgi_app
    response = self.full_dispatch_request()
               ^^^^^^^^^^^^^^^^^^^^^^^^^^^^
  File "/home/jmund/ShockerSecurity/venv/lib/python3.11/site-packages/flask/app.py", line 882, in full_dispatch_request
    rv = self.handle_user_exception(e)
         ^^^^^^^^^^^^^^^^^^^^^^^^^^^^^
  File "/usr/lib/python3/dist-packages/flask_cors/extension.py", line 165, in wrapped_function
    return cors_after_request(app.make_response(f(*args, **kwargs)))
                              ^^^^^^^^^^^^^^^^^^^^^^^^^^^^^^^^^^^^^
  File "/home/jmund/ShockerSecurity/venv/lib/python3.11/site-packages/flask/app.py", line 1174, in make_response
    raise TypeError(
TypeError: The view function for None did not return a valid response. The function either returned None or ended without a return statement.
192.168.157.54 - - [06/Dec/2024 09:52:10] "GET /favicon.ico HTTP/1.1" 500 -
192.168.157.54 - - [06/Dec/2024 09:52:10] "GET /static/faceImages/face_57.jpg HTTP/1.1" 200 -
Error on request:
Traceback (most recent call last):
  File "/home/jmund/ShockerSecurity/venv/lib/python3.11/site-packages/flask/app.py", line 880, in full_dispatch_request
    rv = self.dispatch_request()
         ^^^^^^^^^^^^^^^^^^^^^^^
  File "/home/jmund/ShockerSecurity/venv/lib/python3.11/site-packages/flask/app.py", line 854, in dispatch_request
    self.raise_routing_exception(req)
  File "/home/jmund/ShockerSecurity/venv/lib/python3.11/site-packages/flask/app.py", line 463, in raise_routing_exception
    raise request.routing_exception  # type: ignore[misc]
  File "/home/jmund/ShockerSecurity/venv/lib/python3.11/site-packages/flask/ctx.py", line 362, in match_request
    result = self.url_adapter.match(return_rule=True)  # type: ignore
             ^^^^^^^^^^^^^^^^^^^^^^^^^^^^^^^^^^^^^^^^^^^^^^^^^^^^^^^^
  File "/home/jmund/ShockerSecurity/venv/lib/python3.11/site-packages/werkzeug/routing/map.py", line 629, in match
    raise NotFound() from None
werkzeug.exceptions.NotFound: 404 Not Found: The requested URL was not found on the server. If you entered the URL manually please check your spelling and try again.

During handling of the above exception, another exception occurred:

Traceback (most recent call last):
  File "/home/jmund/ShockerSecurity/venv/lib/python3.11/site-packages/flask/app.py", line 1473, in wsgi_app
    response = self.full_dispatch_request()
               ^^^^^^^^^^^^^^^^^^^^^^^^^^^^
  File "/home/jmund/ShockerSecurity/venv/lib/python3.11/site-packages/flask/app.py", line 882, in full_dispatch_request
    rv = self.handle_user_exception(e)
         ^^^^^^^^^^^^^^^^^^^^^^^^^^^^^
  File "/usr/lib/python3/dist-packages/flask_cors/extension.py", line 165, in wrapped_function
    return cors_after_request(app.make_response(f(*args, **kwargs)))
                              ^^^^^^^^^^^^^^^^^^^^^^^^^^^^^^^^^^^^^^
  File "/home/jmund/ShockerSecurity/venv/lib/python3.11/site-packages/flask/app.py", line 1174, in make_response
    raise TypeError(
TypeError: The view function for None did not return a valid response. The function either returned None or ended without a return statement.

During handling of the above exception, another exception occurred:

Traceback (most recent call last):
  File "/home/jmund/ShockerSecurity/venv/lib/python3.11/site-packages/werkzeug/serving.py", line 370, in run_wsgi
    execute(self.server.app)
  File "/home/jmund/ShockerSecurity/venv/lib/python3.11/site-packages/werkzeug/serving.py", line 331, in execute
    application_iter = app(environ, start_response)
                       ^^^^^^^^^^^^^^^^^^^^^^^^^^^^
  File "/home/jmund/ShockerSecurity/venv/lib/python3.11/site-packages/flask/app.py", line 1498, in __call__
    return self.wsgi_app(environ, start_response)
           ^^^^^^^^^^^^^^^^^^^^^^^^^^^^^^^^^^^^^^
  File "/home/jmund/ShockerSecurity/venv/lib/python3.11/site-packages/flask/app.py", line 1476, in wsgi_app
    response = self.handle_exception(e)
               ^^^^^^^^^^^^^^^^^^^^^^^^
  File "/usr/lib/python3/dist-packages/flask_cors/extension.py", line 165, in wrapped_function
    return cors_after_request(app.make_response(f(*args, **kwargs)))
                                                ^^^^^^^^^^^^^^^^^^^^
  File "/home/jmund/ShockerSecurity/venv/lib/python3.11/site-packages/flask/app.py", line 825, in handle_exception
    return self.finalize_request(server_error, from_error_handler=True)
           ^^^^^^^^^^^^^^^^^^^^^^^^^^^^^^^^^^^^^^^^^^^^^^^^^^^^^^^^^^^^
  File "/home/jmund/ShockerSecurity/venv/lib/python3.11/site-packages/flask/app.py", line 902, in finalize_request
    response = self.make_response(rv)
               ^^^^^^^^^^^^^^^^^^^^^^
  File "/home/jmund/ShockerSecurity/venv/lib/python3.11/site-packages/flask/app.py", line 1174, in make_response
    raise TypeError(
TypeError: The view function for None did not return a valid response. The function either returned None or ended without a return statement.
192.168.157.54 - - [06/Dec/2024 09:52:18] "POST /faces/update HTTP/1.1" 200 -
192.168.157.54 - - [06/Dec/2024 09:52:18] "GET /faces/data HTTP/1.1" 200 -
192.168.157.54 - - [06/Dec/2024 09:52:24] "GET /stream HTTP/1.1" 200 -
192.168.157.54 - - [06/Dec/2024 09:52:24] "GET /static/styles.css HTTP/1.1" 304 -
192.168.157.54 - - [06/Dec/2024 09:52:24] "GET /stream/security_footage HTTP/1.1" 200 -
192.168.157.54 - - [06/Dec/2024 09:52:24] "GET /static/stream.js HTTP/1.1" 304 -
[2024-12-06 09:52:25,116] ERROR in app: Exception on /favicon.ico [GET]
Traceback (most recent call last):
  File "/home/jmund/ShockerSecurity/venv/lib/python3.11/site-packages/flask/app.py", line 880, in full_dispatch_request
    rv = self.dispatch_request()
         ^^^^^^^^^^^^^^^^^^^^^^^
  File "/home/jmund/ShockerSecurity/venv/lib/python3.11/site-packages/flask/app.py", line 854, in dispatch_request
    self.raise_routing_exception(req)
  File "/home/jmund/ShockerSecurity/venv/lib/python3.11/site-packages/flask/app.py", line 463, in raise_routing_exception
    raise request.routing_exception  # type: ignore[misc]
    ^^^^^^^^^^^^^^^^^^^^^^^^^^^^^^^
  File "/home/jmund/ShockerSecurity/venv/lib/python3.11/site-packages/flask/ctx.py", line 362, in match_request
    result = self.url_adapter.match(return_rule=True)  # type: ignore
             ^^^^^^^^^^^^^^^^^^^^^^^^^^^^^^^^^^^^^^^^
  File "/home/jmund/ShockerSecurity/venv/lib/python3.11/site-packages/werkzeug/routing/map.py", line 629, in match
    raise NotFound() from None
werkzeug.exceptions.NotFound: 404 Not Found: The requested URL was not found on the server. If you entered the URL manually please check your spelling and try again.

During handling of the above exception, another exception occurred:

Traceback (most recent call last):
  File "/home/jmund/ShockerSecurity/venv/lib/python3.11/site-packages/flask/app.py", line 1473, in wsgi_app
    response = self.full_dispatch_request()
               ^^^^^^^^^^^^^^^^^^^^^^^^^^^^
  File "/home/jmund/ShockerSecurity/venv/lib/python3.11/site-packages/flask/app.py", line 882, in full_dispatch_request
    rv = self.handle_user_exception(e)
         ^^^^^^^^^^^^^^^^^^^^^^^^^^^^^
  File "/usr/lib/python3/dist-packages/flask_cors/extension.py", line 165, in wrapped_function
    return cors_after_request(app.make_response(f(*args, **kwargs)))
                              ^^^^^^^^^^^^^^^^^^^^^^^^^^^^^^^^^^^^^
  File "/home/jmund/ShockerSecurity/venv/lib/python3.11/site-packages/flask/app.py", line 1174, in make_response
    raise TypeError(
TypeError: The view function for None did not return a valid response. The function either returned None or ended without a return statement.
192.168.157.54 - - [06/Dec/2024 09:52:25] "GET /favicon.ico HTTP/1.1" 500 -
Error on request:
Traceback (most recent call last):
  File "/home/jmund/ShockerSecurity/venv/lib/python3.11/site-packages/flask/app.py", line 880, in full_dispatch_request
    rv = self.dispatch_request()
         ^^^^^^^^^^^^^^^^^^^^^^^
  File "/home/jmund/ShockerSecurity/venv/lib/python3.11/site-packages/flask/app.py", line 854, in dispatch_request
    self.raise_routing_exception(req)
  File "/home/jmund/ShockerSecurity/venv/lib/python3.11/site-packages/flask/app.py", line 463, in raise_routing_exception
    raise request.routing_exception  # type: ignore[misc]
  File "/home/jmund/ShockerSecurity/venv/lib/python3.11/site-packages/flask/ctx.py", line 362, in match_request
    result = self.url_adapter.match(return_rule=True)  # type: ignore
             ^^^^^^^^^^^^^^^^^^^^^^^^^^^^^^^^^^^^^^^^^^^^^^^^^^^^^^^^
  File "/home/jmund/ShockerSecurity/venv/lib/python3.11/site-packages/werkzeug/routing/map.py", line 629, in match
    raise NotFound() from None
werkzeug.exceptions.NotFound: 404 Not Found: The requested URL was not found on the server. If you entered the URL manually please check your spelling and try again.

During handling of the above exception, another exception occurred:

Traceback (most recent call last):
  File "/home/jmund/ShockerSecurity/venv/lib/python3.11/site-packages/flask/app.py", line 1473, in wsgi_app
    response = self.full_dispatch_request()
               ^^^^^^^^^^^^^^^^^^^^^^^^^^^^
  File "/home/jmund/ShockerSecurity/venv/lib/python3.11/site-packages/flask/app.py", line 882, in full_dispatch_request
    rv = self.handle_user_exception(e)
         ^^^^^^^^^^^^^^^^^^^^^^^^^^^^^
  File "/usr/lib/python3/dist-packages/flask_cors/extension.py", line 165, in wrapped_function
    return cors_after_request(app.make_response(f(*args, **kwargs)))
                              ^^^^^^^^^^^^^^^^^^^^^^^^^^^^^^^^^^^^^^
  File "/home/jmund/ShockerSecurity/venv/lib/python3.11/site-packages/flask/app.py", line 1174, in make_response
    raise TypeError(
TypeError: The view function for None did not return a valid response. The function either returned None or ended without a return statement.

During handling of the above exception, another exception occurred:

Traceback (most recent call last):
  File "/home/jmund/ShockerSecurity/venv/lib/python3.11/site-packages/werkzeug/serving.py", line 370, in run_wsgi
    execute(self.server.app)
  File "/home/jmund/ShockerSecurity/venv/lib/python3.11/site-packages/werkzeug/serving.py", line 331, in execute
    application_iter = app(environ, start_response)
                       ^^^^^^^^^^^^^^^^^^^^^^^^^^^^
  File "/home/jmund/ShockerSecurity/venv/lib/python3.11/site-packages/flask/app.py", line 1498, in __call__
    return self.wsgi_app(environ, start_response)
           ^^^^^^^^^^^^^^^^^^^^^^^^^^^^^^^^^^^^^^
  File "/home/jmund/ShockerSecurity/venv/lib/python3.11/site-packages/flask/app.py", line 1476, in wsgi_app
    response = self.handle_exception(e)
               ^^^^^^^^^^^^^^^^^^^^^^^^
  File "/usr/lib/python3/dist-packages/flask_cors/extension.py", line 165, in wrapped_function
    return cors_after_request(app.make_response(f(*args, **kwargs)))
                                                ^^^^^^^^^^^^^^^^^^^^
  File "/home/jmund/ShockerSecurity/venv/lib/python3.11/site-packages/flask/app.py", line 825, in handle_exception
    return self.finalize_request(server_error, from_error_handler=True)
           ^^^^^^^^^^^^^^^^^^^^^^^^^^^^^^^^^^^^^^^^^^^^^^^^^^^^^^^^^^^^
  File "/home/jmund/ShockerSecurity/venv/lib/python3.11/site-packages/flask/app.py", line 902, in finalize_request
    response = self.make_response(rv)
               ^^^^^^^^^^^^^^^^^^^^^^
  File "/home/jmund/ShockerSecurity/venv/lib/python3.11/site-packages/flask/app.py", line 1174, in make_response
    raise TypeError(
TypeError: The view function for None did not return a valid response. The function either returned None or ended without a return statement.
192.168.157.54 - - [06/Dec/2024 09:53:23] "GET /faces HTTP/1.1" 200 -
192.168.157.54 - - [06/Dec/2024 09:53:23] "GET /static/styles.css HTTP/1.1" 304 -
192.168.157.54 - - [06/Dec/2024 09:53:23] "GET /static/manageFaces.js HTTP/1.1" 304 -
/home/jmund/ShockerSecurity/StartShockerSecurity.sh: line 17:  3378 Segmentation fault      python backend/flaskApp.py
StartShockerSecurity.sh bash script exited with code 1!


Commiting logs...
 09:49:36] "POST /faces/delete HTTP/1.1" 200 -
192.168.157.54 - - [06/Dec/2024 09:49:36] "GET /faces/data HTTP/1.1" 200 -
Exception in thread Thread-4 (run_face_recognition):
Traceback (most recent call last):
  File "/usr/lib/python3.11/threading.py", line 1038, in _bootstrap_inner
    self.run()
  File "/usr/lib/python3.11/threading.py", line 975, in run
    self._target(*self._args, **self._kwargs)
  File "/home/jmund/ShockerSecurity/backend/flaskStream.py", line 142, in run_face_recognition
    if not detected_face.accepted:
           ^^^^^^^^^^^^^^^^^^^^^^
AttributeError: 'NoneType' object has no attribute 'accepted'
192.168.157.54 - - [06/Dec/2024 09:49:39] "GET /stream HTTP/1.1" 200 -
192.168.157.54 - - [06/Dec/2024 09:49:39] "GET /static/styles.css HTTP/1.1" 304 -
192.168.157.54 - - [06/Dec/2024 09:49:39] "GET /static/stream.js HTTP/1.1" 304 -
192.168.157.54 - - [06/Dec/2024 09:49:39] "GET /stream/security_footage HTTP/1.1" 200 -
[2024-12-06 09:49:39,259] ERROR in app: Exception on /favicon.ico [GET]
Traceback (most recent call last):
  File "/home/jmund/ShockerSecurity/venv/lib/python3.11/site-packages/flask/app.py", line 880, in full_dispatch_request
    rv = self.dispatch_request()
         ^^^^^^^^^^^^^^^^^^^^^^^
  File "/home/jmund/ShockerSecurity/venv/lib/python3.11/site-packages/flask/app.py", line 854, in dispatch_request
    self.raise_routing_exception(req)
  File "/home/jmund/ShockerSecurity/venv/lib/python3.11/site-packages/flask/app.py", line 463, in raise_routing_exception
    raise request.routing_exception  # type: ignore[misc]
    ^^^^^^^^^^^^^^^^^^^^^^^^^^^^^^^
  File "/home/jmund/ShockerSecurity/venv/lib/python3.11/site-packages/flask/ctx.py", line 362, in match_request
    result = self.url_adapter.match(return_rule=True)  # type: ignore
             ^^^^^^^^^^^^^^^^^^^^^^^^^^^^^^^^^^^^^^^^
  File "/home/jmund/ShockerSecurity/venv/lib/python3.11/site-packages/werkzeug/routing/map.py", line 629, in match
    raise NotFound() from None
werkzeug.exceptions.NotFound: 404 Not Found: The requested URL was not found on the server. If you entered the URL manually please check your spelling and try again.

During handling of the above exception, another exception occurred:

Traceback (most recent call last):
  File "/home/jmund/ShockerSecurity/venv/lib/python3.11/site-packages/flask/app.py", line 1473, in wsgi_app
    response = self.full_dispatch_request()
               ^^^^^^^^^^^^^^^^^^^^^^^^^^^^
  File "/home/jmund/ShockerSecurity/venv/lib/python3.11/site-packages/flask/app.py", line 882, in full_dispatch_request
    rv = self.handle_user_exception(e)
         ^^^^^^^^^^^^^^^^^^^^^^^^^^^^^
  File "/usr/lib/python3/dist-packages/flask_cors/extension.py", line 165, in wrapped_function
    return cors_after_request(app.make_response(f(*args, **kwargs)))
                              ^^^^^^^^^^^^^^^^^^^^^^^^^^^^^^^^^^^^^
  File "/home/jmund/ShockerSecurity/venv/lib/python3.11/site-packages/flask/app.py", line 1174, in make_response
    raise TypeError(
TypeError: The view function for None did not return a valid response. The function either returned None or ended without a return statement.
192.168.157.54 - - [06/Dec/2024 09:49:39] "GET /favicon.ico HTTP/1.1" 500 -
Error on request:
Traceback (most recent call last):
  File "/home/jmund/ShockerSecurity/venv/lib/python3.11/site-packages/flask/app.py", line 880, in full_dispatch_request
    rv = self.dispatch_request()
         ^^^^^^^^^^^^^^^^^^^^^^^
  File "/home/jmund/ShockerSecurity/venv/lib/python3.11/site-packages/flask/app.py", line 854, in dispatch_request
    self.raise_routing_exception(req)
  File "/home/jmund/ShockerSecurity/venv/lib/python3.11/site-packages/flask/app.py", line 463, in raise_routing_exception
    raise request.routing_exception  # type: ignore[misc]
  File "/home/jmund/ShockerSecurity/venv/lib/python3.11/site-packages/flask/ctx.py", line 362, in match_request
    result = self.url_adapter.match(return_rule=True)  # type: ignore
             ^^^^^^^^^^^^^^^^^^^^^^^^^^^^^^^^^^^^^^^^^^^^^^^^^^^^^^^^
  File "/home/jmund/ShockerSecurity/venv/lib/python3.11/site-packages/werkzeug/routing/map.py", line 629, in match
    raise NotFound() from None
werkzeug.exceptions.NotFound: 404 Not Found: The requested URL was not found on the server. If you entered the URL manually please check your spelling and try again.

During handling of the above exception, another exception occurred:

Traceback (most recent call last):
  File "/home/jmund/ShockerSecurity/venv/lib/python3.11/site-packages/flask/app.py", line 1473, in wsgi_app
    response = self.full_dispatch_request()
               ^^^^^^^^^^^^^^^^^^^^^^^^^^^^
  File "/home/jmund/ShockerSecurity/venv/lib/python3.11/site-packages/flask/app.py", line 882, in full_dispatch_request
    rv = self.handle_user_exception(e)
         ^^^^^^^^^^^^^^^^^^^^^^^^^^^^^
  File "/usr/lib/python3/dist-packages/flask_cors/extension.py", line 165, in wrapped_function
    return cors_after_request(app.make_response(f(*args, **kwargs)))
                              ^^^^^^^^^^^^^^^^^^^^^^^^^^^^^^^^^^^^^^
  File "/home/jmund/ShockerSecurity/venv/lib/python3.11/site-packages/flask/app.py", line 1174, in make_response
    raise TypeError(
TypeError: The view function for None did not return a valid response. The function either returned None or ended without a return statement.

During handling of the above exception, another exception occurred:

Traceback (most recent call last):
  File "/home/jmund/ShockerSecurity/venv/lib/python3.11/site-packages/werkzeug/serving.py", line 370, in run_wsgi
    execute(self.server.app)
  File "/home/jmund/ShockerSecurity/venv/lib/python3.11/site-packages/werkzeug/serving.py", line 331, in execute
    application_iter = app(environ, start_response)
                       ^^^^^^^^^^^^^^^^^^^^^^^^^^^^
  File "/home/jmund/ShockerSecurity/venv/lib/python3.11/site-packages/flask/app.py", line 1498, in __call__
    return self.wsgi_app(environ, start_response)
           ^^^^^^^^^^^^^^^^^^^^^^^^^^^^^^^^^^^^^^
  File "/home/jmund/ShockerSecurity/venv/lib/python3.11/site-packages/flask/app.py", line 1476, in wsgi_app
    response = self.handle_exception(e)
               ^^^^^^^^^^^^^^^^^^^^^^^^
  File "/usr/lib/python3/dist-packages/flask_cors/extension.py", line 165, in wrapped_function
    return cors_after_request(app.make_response(f(*args, **kwargs)))
                                                ^^^^^^^^^^^^^^^^^^^^
  File "/home/jmund/ShockerSecurity/venv/lib/python3.11/site-packages/flask/app.py", line 825, in handle_exception
    return self.finalize_request(server_error, from_error_handler=True)
           ^^^^^^^^^^^^^^^^^^^^^^^^^^^^^^^^^^^^^^^^^^^^^^^^^^^^^^^^^^^^
  File "/home/jmund/ShockerSecurity/venv/lib/python3.11/site-packages/flask/app.py", line 902, in finalize_request
    response = self.make_response(rv)
               ^^^^^^^^^^^^^^^^^^^^^^
  File "/home/jmund/ShockerSecurity/venv/lib/python3.11/site-packages/flask/app.py", line 1174, in make_response
    raise TypeError(
TypeError: The view function for None did not return a valid response. The function either returned None or ended without a return statement.
192.168.157.54 - - [06/Dec/2024 09:51:01] "GET /faces HTTP/1.1" 200 -
192.168.157.54 - - [06/Dec/2024 09:51:01] "GET /static/styles.css HTTP/1.1" 304 -
192.168.157.54 - - [06/Dec/2024 09:51:01] "GET /static/manageFaces.js HTTP/1.1" 304 -
192.168.157.54 - - [06/Dec/2024 09:51:01] "GET /faces/data HTTP/1.1" 200 -
[2024-12-06 09:51:01,652] ERROR in app: Exception on /favicon.ico [GET]
Traceback (most recent call last):
  File "/home/jmund/ShockerSecurity/venv/lib/python3.11/site-packages/flask/app.py", line 880, in full_dispatch_request
    rv = self.dispatch_request()
         ^^^^^^^^^^^^^^^^^^^^^^^
  File "/home/jmund/ShockerSecurity/venv/lib/python3.11/site-packages/flask/app.py", line 854, in dispatch_request
    self.raise_routing_exception(req)
  File "/home/jmund/ShockerSecurity/venv/lib/python3.11/site-packages/flask/app.py", line 463, in raise_routing_exception
    raise request.routing_exception  # type: ignore[misc]
    ^^^^^^^^^^^^^^^^^^^^^^^^^^^^^^^
  File "/home/jmund/ShockerSecurity/venv/lib/python3.11/site-packages/flask/ctx.py", line 362, in match_request
    result = self.url_adapter.match(return_rule=True)  # type: ignore
             ^^^^^^^^^^^^^^^^^^^^^^^^^^^^^^^^^^^^^^^^
  File "/home/jmund/ShockerSecurity/venv/lib/python3.11/site-packages/werkzeug/routing/map.py", line 629, in match
    raise NotFound() from None
werkzeug.exceptions.NotFound: 404 Not Found: The requested URL was not found on the server. If you entered the URL manually please check your spelling and try again.

During handling of the above exception, another exception occurred:

Traceback (most recent call last):
  File "/home/jmund/ShockerSecurity/venv/lib/python3.11/site-packages/flask/app.py", line 1473, in wsgi_app
    response = self.full_dispatch_request()
               ^^^^^^^^^^^^^^^^^^^^^^^^^^^^
  File "/home/jmund/ShockerSecurity/venv/lib/python3.11/site-packages/flask/app.py", line 882, in full_dispatch_request
    rv = self.handle_user_exception(e)
         ^^^^^^^^^^^^^^^^^^^^^^^^^^^^^
  File "/usr/lib/python3/dist-packages/flask_cors/extension.py", line 165, in wrapped_function
    return cors_after_request(app.make_response(f(*args, **kwargs)))
                              ^^^^^^^^^^^^^^^^^^^^^^^^^^^^^^^^^^^^^
  File "/home/jmund/ShockerSecurity/venv/lib/python3.11/site-packages/flask/app.py", line 1174, in make_response
    raise TypeError(
TypeError: The view function for None did not return a valid response. The function either returned None or ended without a return statement.
192.168.157.54 - - [06/Dec/2024 09:51:01] "GET /favicon.ico HTTP/1.1" 500 -
Error on request:
Traceback (most recent call last):
  File "/home/jmund/ShockerSecurity/venv/lib/python3.11/site-packages/flask/app.py", line 880, in full_dispatch_request
    rv = self.dispatch_request()
         ^^^^^^^^^^^^^^^^^^^^^^^
  File "/home/jmund/ShockerSecurity/venv/lib/python3.11/site-packages/flask/app.py", line 854, in dispatch_request
    self.raise_routing_exception(req)
  File "/home/jmund/ShockerSecurity/venv/lib/python3.11/site-packages/flask/app.py", line 463, in raise_routing_exception
    raise request.routing_exception  # type: ignore[misc]
  File "/home/jmund/ShockerSecurity/venv/lib/python3.11/site-packages/flask/ctx.py", line 362, in match_request
    result = self.url_adapter.match(return_rule=True)  # type: ignore
             ^^^^^^^^^^^^^^^^^^^^^^^^^^^^^^^^^^^^^^^^^^^^^^^^^^^^^^^^
  File "/home/jmund/ShockerSecurity/venv/lib/python3.11/site-packages/werkzeug/routing/map.py", line 629, in match
    raise NotFound() from None
werkzeug.exceptions.NotFound: 404 Not Found: The requested URL was not found on the server. If you entered the URL manually please check your spelling and try again.

During handling of the above exception, another exception occurred:

Traceback (most recent call last):
  File "/home/jmund/ShockerSecurity/venv/lib/python3.11/site-packages/flask/app.py", line 1473, in wsgi_app
    response = self.full_dispatch_request()
               ^^^^^^^^^^^^^^^^^^^^^^^^^^^^
  File "/home/jmund/ShockerSecurity/venv/lib/python3.11/site-packages/flask/app.py", line 882, in full_dispatch_request
    rv = self.handle_user_exception(e)
         ^^^^^^^^^^^^^^^^^^^^^^^^^^^^^
  File "/usr/lib/python3/dist-packages/flask_cors/extension.py", line 165, in wrapped_function
    return cors_after_request(app.make_response(f(*args, **kwargs)))
                              ^^^^^^^^^^^^^^^^^^^^^^^^^^^^^^^^^^^^^^
  File "/home/jmund/ShockerSecurity/venv/lib/python3.11/site-packages/flask/app.py", line 1174, in make_response
    raise TypeError(
TypeError: The view function for None did not return a valid response. The function either returned None or ended without a return statement.

During handling of the above exception, another exception occurred:

Traceback (most recent call last):
  File "/home/jmund/ShockerSecurity/venv/lib/python3.11/site-packages/werkzeug/serving.py", line 370, in run_wsgi
    execute(self.server.app)
  File "/home/jmund/ShockerSecurity/venv/lib/python3.11/site-packages/werkzeug/serving.py", line 331, in execute
    application_iter = app(environ, start_response)
                       ^^^^^^^^^^^^^^^^^^^^^^^^^^^^
  File "/home/jmund/ShockerSecurity/venv/lib/python3.11/site-packages/flask/app.py", line 1498, in __call__
    return self.wsgi_app(environ, start_response)
           ^^^^^^^^^^^^^^^^^^^^^^^^^^^^^^^^^^^^^^
  File "/home/jmund/ShockerSecurity/venv/lib/python3.11/site-packages/flask/app.py", line 1476, in wsgi_app
    response = self.handle_exception(e)
               ^^^^^^^^^^^^^^^^^^^^^^^^
  File "/usr/lib/python3/dist-packages/flask_cors/extension.py", line 165, in wrapped_function
    return cors_after_request(app.make_response(f(*args, **kwargs)))
                                                ^^^^^^^^^^^^^^^^^^^^
  File "/home/jmund/ShockerSecurity/venv/lib/python3.11/site-packages/flask/app.py", line 825, in handle_exception
    return self.finalize_request(server_error, from_error_handler=True)
           ^^^^^^^^^^^^^^^^^^^^^^^^^^^^^^^^^^^^^^^^^^^^^^^^^^^^^^^^^^^^
  File "/home/jmund/ShockerSecurity/venv/lib/python3.11/site-packages/flask/app.py", line 902, in finalize_request
    response = self.make_response(rv)
               ^^^^^^^^^^^^^^^^^^^^^^
  File "/home/jmund/ShockerSecurity/venv/lib/python3.11/site-packages/flask/app.py", line 1174, in make_response
    raise TypeError(
TypeError: The view function for None did not return a valid response. The function either returned None or ended without a return statement.
192.168.157.54 - - [06/Dec/2024 09:51:03] "GET /faces HTTP/1.1" 200 -
192.168.157.54 - - [06/Dec/2024 09:51:03] "GET /static/styles.css HTTP/1.1" 304 -
192.168.157.54 - - [06/Dec/2024 09:51:03] "GET /static/manageFaces.js HTTP/1.1" 304 -
192.168.157.54 - - [06/Dec/2024 09:51:03] "GET /faces/data HTTP/1.1" 200 -
[2024-12-06 09:51:03,273] ERROR in app: Exception on /favicon.ico [GET]
Traceback (most recent call last):
  File "/home/jmund/ShockerSecurity/venv/lib/python3.11/site-packages/flask/app.py", line 880, in full_dispatch_request
    rv = self.dispatch_request()
         ^^^^^^^^^^^^^^^^^^^^^^^
  File "/home/jmund/ShockerSecurity/venv/lib/python3.11/site-packages/flask/app.py", line 854, in dispatch_request
    self.raise_routing_exception(req)
  File "/home/jmund/ShockerSecurity/venv/lib/python3.11/site-packages/flask/app.py", line 463, in raise_routing_exception
    raise request.routing_exception  # type: ignore[misc]
    ^^^^^^^^^^^^^^^^^^^^^^^^^^^^^^^
  File "/home/jmund/ShockerSecurity/venv/lib/python3.11/site-packages/flask/ctx.py", line 362, in match_request
    result = self.url_adapter.match(return_rule=True)  # type: ignore
             ^^^^^^^^^^^^^^^^^^^^^^^^^^^^^^^^^^^^^^^^
  File "/home/jmund/ShockerSecurity/venv/lib/python3.11/site-packages/werkzeug/routing/map.py", line 629, in match
    raise NotFound() from None
werkzeug.exceptions.NotFound: 404 Not Found: The requested URL was not found on the server. If you entered the URL manually please check your spelling and try again.

During handling of the above exception, another exception occurred:

Traceback (most recent call last):
  File "/home/jmund/ShockerSecurity/venv/lib/python3.11/site-packages/flask/app.py", line 1473, in wsgi_app
    response = self.full_dispatch_request()
               ^^^^^^^^^^^^^^^^^^^^^^^^^^^^
  File "/home/jmund/ShockerSecurity/venv/lib/python3.11/site-packages/flask/app.py", line 882, in full_dispatch_request
    rv = self.handle_user_exception(e)
         ^^^^^^^^^^^^^^^^^^^^^^^^^^^^^
  File "/usr/lib/python3/dist-packages/flask_cors/extension.py", line 165, in wrapped_function
    return cors_after_request(app.make_response(f(*args, **kwargs)))
                              ^^^^^^^^^^^^^^^^^^^^^^^^^^^^^^^^^^^^^
  File "/home/jmund/ShockerSecurity/venv/lib/python3.11/site-packages/flask/app.py", line 1174, in make_response
    raise TypeError(
TypeError: The view function for None did not return a valid response. The function either returned None or ended without a return statement.
192.168.157.54 - - [06/Dec/2024 09:51:03] "GET /favicon.ico HTTP/1.1" 500 -
Error on request:
Traceback (most recent call last):
  File "/home/jmund/ShockerSecurity/venv/lib/python3.11/site-packages/flask/app.py", line 880, in full_dispatch_request
    rv = self.dispatch_request()
         ^^^^^^^^^^^^^^^^^^^^^^^
  File "/home/jmund/ShockerSecurity/venv/lib/python3.11/site-packages/flask/app.py", line 854, in dispatch_request
    self.raise_routing_exception(req)
  File "/home/jmund/ShockerSecurity/venv/lib/python3.11/site-packages/flask/app.py", line 463, in raise_routing_exception
    raise request.routing_exception  # type: ignore[misc]
  File "/home/jmund/ShockerSecurity/venv/lib/python3.11/site-packages/flask/ctx.py", line 362, in match_request
    result = self.url_adapter.match(return_rule=True)  # type: ignore
             ^^^^^^^^^^^^^^^^^^^^^^^^^^^^^^^^^^^^^^^^^^^^^^^^^^^^^^^^
  File "/home/jmund/ShockerSecurity/venv/lib/python3.11/site-packages/werkzeug/routing/map.py", line 629, in match
    raise NotFound() from None
werkzeug.exceptions.NotFound: 404 Not Found: The requested URL was not found on the server. If you entered the URL manually please check your spelling and try again.

During handling of the above exception, another exception occurred:

Traceback (most recent call last):
  File "/home/jmund/ShockerSecurity/venv/lib/python3.11/site-packages/flask/app.py", line 1473, in wsgi_app
    response = self.full_dispatch_request()
               ^^^^^^^^^^^^^^^^^^^^^^^^^^^^
  File "/home/jmund/ShockerSecurity/venv/lib/python3.11/site-packages/flask/app.py", line 882, in full_dispatch_request
    rv = self.handle_user_exception(e)
         ^^^^^^^^^^^^^^^^^^^^^^^^^^^^^
  File "/usr/lib/python3/dist-packages/flask_cors/extension.py", line 165, in wrapped_function
    return cors_after_request(app.make_response(f(*args, **kwargs)))
                              ^^^^^^^^^^^^^^^^^^^^^^^^^^^^^^^^^^^^^^
  File "/home/jmund/ShockerSecurity/venv/lib/python3.11/site-packages/flask/app.py", line 1174, in make_response
    raise TypeError(
TypeError: The view function for None did not return a valid response. The function either returned None or ended without a return statement.

During handling of the above exception, another exception occurred:

Traceback (most recent call last):
  File "/home/jmund/ShockerSecurity/venv/lib/python3.11/site-packages/werkzeug/serving.py", line 370, in run_wsgi
    execute(self.server.app)
  File "/home/jmund/ShockerSecurity/venv/lib/python3.11/site-packages/werkzeug/serving.py", line 331, in execute
    application_iter = app(environ, start_response)
                       ^^^^^^^^^^^^^^^^^^^^^^^^^^^^
  File "/home/jmund/ShockerSecurity/venv/lib/python3.11/site-packages/flask/app.py", line 1498, in __call__
    return self.wsgi_app(environ, start_response)
           ^^^^^^^^^^^^^^^^^^^^^^^^^^^^^^^^^^^^^^
  File "/home/jmund/ShockerSecurity/venv/lib/python3.11/site-packages/flask/app.py", line 1476, in wsgi_app
    response = self.handle_exception(e)
               ^^^^^^^^^^^^^^^^^^^^^^^^
  File "/usr/lib/python3/dist-packages/flask_cors/extension.py", line 165, in wrapped_function
    return cors_after_request(app.make_response(f(*args, **kwargs)))
                                                ^^^^^^^^^^^^^^^^^^^^
  File "/home/jmund/ShockerSecurity/venv/lib/python3.11/site-packages/flask/app.py", line 825, in handle_exception
    return self.finalize_request(server_error, from_error_handler=True)
           ^^^^^^^^^^^^^^^^^^^^^^^^^^^^^^^^^^^^^^^^^^^^^^^^^^^^^^^^^^^^
  File "/home/jmund/ShockerSecurity/venv/lib/python3.11/site-packages/flask/app.py", line 902, in finalize_request
    response = self.make_response(rv)
               ^^^^^^^^^^^^^^^^^^^^^^
  File "/home/jmund/ShockerSecurity/venv/lib/python3.11/site-packages/flask/app.py", line 1174, in make_response
    raise TypeError(
TypeError: The view function for None did not return a valid response. The function either returned None or ended without a return statement.
192.168.157.54 - - [06/Dec/2024 09:51:04] "GET /stream HTTP/1.1" 200 -
192.168.157.54 - - [06/Dec/2024 09:51:04] "GET /static/styles.css HTTP/1.1" 304 -
192.168.157.54 - - [06/Dec/2024 09:51:04] "GET /static/stream.js HTTP/1.1" 304 -
192.168.157.54 - - [06/Dec/2024 09:51:04] "GET /stream/security_footage HTTP/1.1" 200 -
[2024-12-06 09:51:04,440] ERROR in app: Exception on /favicon.ico [GET]
Traceback (most recent call last):
  File "/home/jmund/ShockerSecurity/venv/lib/python3.11/site-packages/flask/app.py", line 880, in full_dispatch_request
    rv = self.dispatch_request()
         ^^^^^^^^^^^^^^^^^^^^^^^
  File "/home/jmund/ShockerSecurity/venv/lib/python3.11/site-packages/flask/app.py", line 854, in dispatch_request
    self.raise_routing_exception(req)
  File "/home/jmund/ShockerSecurity/venv/lib/python3.11/site-packages/flask/app.py", line 463, in raise_routing_exception
    raise request.routing_exception  # type: ignore[misc]
    ^^^^^^^^^^^^^^^^^^^^^^^^^^^^^^^
  File "/home/jmund/ShockerSecurity/venv/lib/python3.11/site-packages/flask/ctx.py", line 362, in match_request
    result = self.url_adapter.match(return_rule=True)  # type: ignore
             ^^^^^^^^^^^^^^^^^^^^^^^^^^^^^^^^^^^^^^^^
  File "/home/jmund/ShockerSecurity/venv/lib/python3.11/site-packages/werkzeug/routing/map.py", line 629, in match
    raise NotFound() from None
werkzeug.exceptions.NotFound: 404 Not Found: The requested URL was not found on the server. If you entered the URL manually please check your spelling and try again.

During handling of the above exception, another exception occurred:

Traceback (most recent call last):
  File "/home/jmund/ShockerSecurity/venv/lib/python3.11/site-packages/flask/app.py", line 1473, in wsgi_app
    response = self.full_dispatch_request()
               ^^^^^^^^^^^^^^^^^^^^^^^^^^^^
  File "/home/jmund/ShockerSecurity/venv/lib/python3.11/site-packages/flask/app.py", line 882, in full_dispatch_request
    rv = self.handle_user_exception(e)
         ^^^^^^^^^^^^^^^^^^^^^^^^^^^^^
  File "/usr/lib/python3/dist-packages/flask_cors/extension.py", line 165, in wrapped_function
    return cors_after_request(app.make_response(f(*args, **kwargs)))
                              ^^^^^^^^^^^^^^^^^^^^^^^^^^^^^^^^^^^^^
  File "/home/jmund/ShockerSecurity/venv/lib/python3.11/site-packages/flask/app.py", line 1174, in make_response
    raise TypeError(
TypeError: The view function for None did not return a valid response. The function either returned None or ended without a return statement.
192.168.157.54 - - [06/Dec/2024 09:51:04] "GET /favicon.ico HTTP/1.1" 500 -
Error on request:
Traceback (most recent call last):
  File "/home/jmund/ShockerSecurity/venv/lib/python3.11/site-packages/flask/app.py", line 880, in full_dispatch_request
    rv = self.dispatch_request()
         ^^^^^^^^^^^^^^^^^^^^^^^
  File "/home/jmund/ShockerSecurity/venv/lib/python3.11/site-packages/flask/app.py", line 854, in dispatch_request
    self.raise_routing_exception(req)
  File "/home/jmund/ShockerSecurity/venv/lib/python3.11/site-packages/flask/app.py", line 463, in raise_routing_exception
    raise request.routing_exception  # type: ignore[misc]
  File "/home/jmund/ShockerSecurity/venv/lib/python3.11/site-packages/flask/ctx.py", line 362, in match_request
    result = self.url_adapter.match(return_rule=True)  # type: ignore
             ^^^^^^^^^^^^^^^^^^^^^^^^^^^^^^^^^^^^^^^^^^^^^^^^^^^^^^^^
  File "/home/jmund/ShockerSecurity/venv/lib/python3.11/site-packages/werkzeug/routing/map.py", line 629, in match
    raise NotFound() from None
werkzeug.exceptions.NotFound: 404 Not Found: The requested URL was not found on the server. If you entered the URL manually please check your spelling and try again.

During handling of the above exception, another exception occurred:

Traceback (most recent call last):
  File "/home/jmund/ShockerSecurity/venv/lib/python3.11/site-packages/flask/app.py", line 1473, in wsgi_app
    response = self.full_dispatch_request()
               ^^^^^^^^^^^^^^^^^^^^^^^^^^^^
  File "/home/jmund/ShockerSecurity/venv/lib/python3.11/site-packages/flask/app.py", line 882, in full_dispatch_request
    rv = self.handle_user_exception(e)
         ^^^^^^^^^^^^^^^^^^^^^^^^^^^^^
  File "/usr/lib/python3/dist-packages/flask_cors/extension.py", line 165, in wrapped_function
    return cors_after_request(app.make_response(f(*args, **kwargs)))
                              ^^^^^^^^^^^^^^^^^^^^^^^^^^^^^^^^^^^^^^
  File "/home/jmund/ShockerSecurity/venv/lib/python3.11/site-packages/flask/app.py", line 1174, in make_response
    raise TypeError(
TypeError: The view function for None did not return a valid response. The function either returned None or ended without a return statement.

During handling of the above exception, another exception occurred:

Traceback (most recent call last):
  File "/home/jmund/ShockerSecurity/venv/lib/python3.11/site-packages/werkzeug/serving.py", line 370, in run_wsgi
    execute(self.server.app)
  File "/home/jmund/ShockerSecurity/venv/lib/python3.11/site-packages/werkzeug/serving.py", line 331, in execute
    application_iter = app(environ, start_response)
                       ^^^^^^^^^^^^^^^^^^^^^^^^^^^^
  File "/home/jmund/ShockerSecurity/venv/lib/python3.11/site-packages/flask/app.py", line 1498, in __call__
    return self.wsgi_app(environ, start_response)
           ^^^^^^^^^^^^^^^^^^^^^^^^^^^^^^^^^^^^^^
  File "/home/jmund/ShockerSecurity/venv/lib/python3.11/site-packages/flask/app.py", line 1476, in wsgi_app
    response = self.handle_exception(e)
               ^^^^^^^^^^^^^^^^^^^^^^^^
  File "/usr/lib/python3/dist-packages/flask_cors/extension.py", line 165, in wrapped_function
    return cors_after_request(app.make_response(f(*args, **kwargs)))
                                                ^^^^^^^^^^^^^^^^^^^^
  File "/home/jmund/ShockerSecurity/venv/lib/python3.11/site-packages/flask/app.py", line 825, in handle_exception
    return self.finalize_request(server_error, from_error_handler=True)
           ^^^^^^^^^^^^^^^^^^^^^^^^^^^^^^^^^^^^^^^^^^^^^^^^^^^^^^^^^^^^
  File "/home/jmund/ShockerSecurity/venv/lib/python3.11/site-packages/flask/app.py", line 902, in finalize_request
    response = self.make_response(rv)
               ^^^^^^^^^^^^^^^^^^^^^^
  File "/home/jmund/ShockerSecurity/venv/lib/python3.11/site-packages/flask/app.py", line 1174, in make_response
    raise TypeError(
TypeError: The view function for None did not return a valid response. The function either returned None or ended without a return statement.
